ERROR log Internal Server Error: /library/user/issue 2022-11-07 11:39:20,545
Traceback (most recent call last):
  File "/home/pearlsoft/.local/share/virtualenvs/Task-nRL4uYOH/lib/python3.8/site-packages/django/core/handlers/exception.py", line 55, in inner
    response = get_response(request)
  File "/home/pearlsoft/.local/share/virtualenvs/Task-nRL4uYOH/lib/python3.8/site-packages/django/core/handlers/base.py", line 197, in _get_response
    response = wrapped_callback(request, *callback_args, **callback_kwargs)
  File "/home/pearlsoft/.local/share/virtualenvs/Task-nRL4uYOH/lib/python3.8/site-packages/django/views/decorators/csrf.py", line 54, in wrapped_view
    return view_func(*args, **kwargs)
  File "/home/pearlsoft/.local/share/virtualenvs/Task-nRL4uYOH/lib/python3.8/site-packages/django/views/generic/base.py", line 103, in view
    return self.dispatch(request, *args, **kwargs)
  File "/home/pearlsoft/.local/share/virtualenvs/Task-nRL4uYOH/lib/python3.8/site-packages/rest_framework/views.py", line 511, in dispatch
    self.response = self.finalize_response(request, response, *args, **kwargs)
  File "/home/pearlsoft/.local/share/virtualenvs/Task-nRL4uYOH/lib/python3.8/site-packages/rest_framework/views.py", line 423, in finalize_response
    assert isinstance(response, HttpResponseBase), (
AssertionError: Expected a `Response`, `HttpResponse` or `HttpStreamingResponse` to be returned from the view, but received a `<class 'NoneType'>`
ERROR basehttp "POST /library/user/issue HTTP/1.1" 500 82430 2022-11-07 11:39:20,546
ERROR views issue failed....!!!!!! 2022-11-07 11:40:24,647
